<robot name="double_pendule">
    <link name="world"/>

    <link name="link2">
        <visual>
            <origin xyz="0.5 0 0" rpy="0 -1.5707963267948966 0" />
            <geometry>
                <cylinder radius="0.1" length="1"/>
            </geometry>
            <material name="Grey">
                <color rgba="0.6 0.6 0.6 1"/>
            </material>
        </visual>
        <collision>
            <origin xyz="0.5 0 0" rpy="0 0 0" />
            <geometry>
                <cylinder radius="0.1" length="1"/>
            </geometry>
        </collision>
    </link>

    <link name="link3">
        <visual>
            <origin xyz="0.5 0 0" rpy="0 1.5707963267948966 0" />
            <geometry>
                <cylinder radius="0.1" length="1"/>
            </geometry>
            <material name="Grey1">
                <color rgba="0.3 0.3 0.3 1"/>
            </material>
        </visual>
        <collision>
            <origin xyz="0.5 0 0" rpy="0 0 0" />
            <geometry>
                <cylinder radius="0.1" length="1"/>
            </geometry>
        </collision>
    </link>

    <joint name="joint1" type="continuous">
        <axis xyz="0 0 1"/>
        <parent link="world"/>
        <child link="link2"/>
        <origin xyz="0 0 0" rpy="3.141592653589793 -1.5707963267948966 0" />
    </joint>

    <joint name="joint2" type="continuous">
        <axis xyz="0 0 1"/>
        <parent link="link2"/>
        <child link="link3"/>
        <origin xyz="1 0 0" rpy="0 0 0" />
    </joint>

    <link name="Outil">
        <visual>
            <origin xyz="0 0.0 0.0"/>
            <geometry>
                <sphere radius="0.05"/>
            </geometry>
            <material name="Green">
                <color rgba="0.0 1 0.0 1.0"/>
            </material>
        </visual>
    </link>

    <joint name="Joint_Outil" type="fixed">
        <parent link="link3"/>
        <child link="Outil"/>
        <origin xyz="1 0 0" rpy="0 0 0" />
    </joint>
</robot>